test_anagram (__main__.TestExercice) ... FAIL
test_doubles (__main__.TestExercice) ... FAIL
test_grades (__main__.TestExercice) ... FAIL
test_histogram (__main__.TestExercice) ... FAIL
test_order (__main__.TestExercice) ... ERROR

======================================================================
ERROR: test_order (__main__.TestExercice)
----------------------------------------------------------------------
Traceback (most recent call last):
  File "test_exercice.py", line 19, in test_order
    output = [exercice.order(v) for v in values]
  File "test_exercice.py", line 19, in <listcomp>
    output = [exercice.order(v) for v in values]
  File "/home/runner/work/c03_ch6_exercices-WassimKeddache/c03_ch6_exercices-WassimKeddache/exercice.py", line 14, in order
    return resultat
UnboundLocalError: local variable 'resultat' referenced before assignment

======================================================================
FAIL: test_anagram (__main__.TestExercice)
----------------------------------------------------------------------
Traceback (most recent call last):
  File "test_exercice.py", line 40, in test_anagram
    'Erreur dans la vérification de l\'anagramme'
AssertionError: Lists differ: [None, None] != [True, False]

First differing element 0:
None
True

- [None, None]
+ [True, False] : Erreur dans la vérification de l'anagramme

======================================================================
FAIL: test_doubles (__main__.TestExercice)
----------------------------------------------------------------------
Traceback (most recent call last):
  File "test_exercice.py", line 55, in test_doubles
    'Erreur dans les doublons'
AssertionError: Lists differ: [False, False] != [False, True]

First differing element 1:
False
True

- [False, False]
+ [False, True] : Erreur dans les doublons

======================================================================
FAIL: test_grades (__main__.TestExercice)
----------------------------------------------------------------------
Traceback (most recent call last):
  File "test_exercice.py", line 69, in test_grades
    'Erreur dans les notes'
AssertionError: [{}] is not an instance of <class 'dict'> : First argument is not a dictionary

======================================================================
FAIL: test_histogram (__main__.TestExercice)
----------------------------------------------------------------------
Traceback (most recent call last):
  File "test_exercice.py", line 84, in test_histogram
    'Erreur dans les histogrammes'
AssertionError: [({}, []), ({}, [])] is not an instance of <class 'dict'> : First argument is not a dictionary

----------------------------------------------------------------------
Ran 5 tests in 0.001s

FAILED (failures=4, errors=1)
